Workbook

Sheet Dashboard
B1: SMR vs alternatives — digital-twin financial model (Stalowa Wola, BWRX-300)
B2: AM R&D / EnergyScope · real PLN 2026 · hourly dispatch from the Python twin (smrtwin) · all formulas live
B3: Assumption case | C3: CENTRAL | D3: LOW = every parameter at its low value (cheap SMR AND low prices); use Input to mix cases.
B4: Case index (1 = LOW, 2 = CENTRAL, 3 = HIGH) | C4: =MATCH(C3,{"LOW","CENTRAL","HIGH"},0) -> 2
B6: Key results by scenario (selected case)
B7: Scenario | C7: NPV post-tax (m PLN) | D7: IRR post-tax | E7: LCOE (PLN/MWh) | F7: Levelised revenue (PLN/MWh) | G7: Avg capacity factor | H7: Local gov. revenue (m PLN/op-yr) | I7: CfD/support PV (m PLN) | J7: Break-even strike / premium (PLN/MWh)
B8: SMR · CfD (two-way, PEJ template) | C8: =Model_SMR_CfD!$D$105 -> 501.54656 | D8: =Model_SMR_CfD!$D$107 -> 0.052593 | E8: =Model_SMR_CfD!$D$119 -> 487.94313 | F8: =Model_SMR_CfD!$D$120 -> 533.57714 | G8: =Model_SMR_CfD!$D$121 -> 0.91178077 | H8: =Model_SMR_CfD!$D$140 -> 78.399928 | I8: =Model_SMR_CfD!$D$122 -> 5501.49 | J8: =Model_SMR_CfD!$D$123 -> 120.84834
B9: SMR · fixed price = last-12-month average spot | C9: =Model_SMR_Fixed!$D$102 -> -821.15934 | D9: =Model_SMR_Fixed!$D$104 -> 0.045942837 | E9: =Model_SMR_Fixed!$D$116 -> 479.35669 | F9: =Model_SMR_Fixed!$D$117 -> 483.39 | G9: =Model_SMR_Fixed!$D$118 -> 0.93709361 | H9: =Model_SMR_Fixed!$D$137 -> 78.094634 | I9: =Model_SMR_Fixed!$D$119 -> 0 | J9: =Model_SMR_Fixed!$D$120 -> 26.474515
B10: SMR · merchant, dynamic 50–100 % dispatch | C10: =Model_SMR_Dynamic!$D$101 -> -5904.5069 | D10: =Model_SMR_Dynamic!$D$103 -> 0.028078146 | E10: =Model_SMR_Dynamic!$D$115 -> 629.40754 | F10: =Model_SMR_Dynamic!$D$116 -> 401.9501 | G10: =Model_SMR_Dynamic!$D$117 -> 0.88969251 | H10: =Model_SMR_Dynamic!$D$136 -> 63.914606 | I10: =Model_SMR_Dynamic!$D$118 -> 0 | J10: =Model_SMR_Dynamic!$D$119 -> 291.51366
B11: CCGT 1+1 ~300 MW · merchant dynamic | C11: =Model_CCGT!$D$100 -> -1718.6727 | D11: =Model_CCGT!$D$102 -> n/a | E11: =Model_CCGT!$D$114 -> 958.88997 | F11: =Model_CCGT!$D$115 -> 633.17192 | G11: =Model_CCGT!$D$116 -> 0.17191977 | H11: =Model_CCGT!$D$135 -> 6.0621583 | I11: =Model_CCGT!$D$117 -> 0 | J11: =Model_CCGT!$D$118 -> 402.12105
B12: OCGT 2×150 MW · merchant dynamic | C12: =Model_OCGT!$D$100 -> -998.17669 | D12: =Model_OCGT!$D$102 -> n/a | E12: =Model_OCGT!$D$114 -> 1857.9693 | F12: =Model_OCGT!$D$115 -> 1060.5848 | G12: =Model_OCGT!$D$116 -> 0.037266172 | H12: =Model_OCGT!$D$135 -> 2.5685396 | I12: =Model_OCGT!$D$117 -> 0 | J12: =Model_OCGT!$D$118 -> 984.42538
B13: Gas engines 4×76.5 MW · merchant dynamic | C13: =Model_Engines!$D$100 -> -221.94746 | D13: =Model_Engines!$D$102 -> -0.26465621 | E13: =Model_Engines!$D$114 -> 1098.9469 | F13: =Model_Engines!$D$115 -> 797.03141 | G13: =Model_Engines!$D$116 -> 0.096557306 | H13: =Model_Engines!$D$135 -> 0.79741117 | I13: =Model_Engines!$D$117 -> 0 | J13: =Model_Engines!$D$118 -> 373.42931
B15: Break-even column: for the CfD sheet = strike (EUR/MWh) at which NPV = 0 (pre-tax exact / post-tax approximated as linear in strike); for other sheets = constant PLN/MWh premium on all output needed for NPV = 0.
B16: 'Alternative cost' reading: NPV of a merchant asset = value of its output at market prices − its full cost, i.e. minus the net cost to the system of building it instead of buying from the market.
B18: Key figures by year — selected case (m PLN)
B19: Year | C19: 2030 | D19: 2035 | E19: 2040 | F19: 2045 | G19: 2050 | H19: 2055 | I19: 2060 | J19: 2065 | K19: 2070
B20: SMR · CfD (two-way, PEJ template) — post-tax FCF | C20: =Model_SMR_CfD!J102 -> -1948.2073 | D20: =Model_SMR_CfD!O102 -> 818.75689 | E20: =Model_SMR_CfD!T102 -> 885.35843 | F20: =Model_SMR_CfD!Y102 -> 840.37602 | G20: =Model_SMR_CfD!AD102 -> 785.01443 | H20: =Model_SMR_CfD!AI102 -> 745.27054 | I20: =Model_SMR_CfD!AN102 -> 729.197 | J20: =Model_SMR_CfD!AS102 -> 769.00426 | K20: =Model_SMR_CfD!AX102 -> 729.2079
B21: SMR · CfD (two-way, PEJ template) — revenue | C21: =Model_SMR_CfD!J69 -> 0 | D21: =Model_SMR_CfD!O69 -> 1331.9653 | E21: =Model_SMR_CfD!T69 -> 1317.9867 | F21: =Model_SMR_CfD!Y69 -> 1317.9955 | G21: =Model_SMR_CfD!AD69 -> 1374.4562 | H21: =Model_SMR_CfD!AI69 -> 1318.0599 | I21: =Model_SMR_CfD!AN69 -> 1318.1157 | J21: =Model_SMR_CfD!AS69 -> 1374.5809 | K21: =Model_SMR_CfD!AX69 -> 1318.1292
B22: SMR · CfD (two-way, PEJ template) — local gov. revenue | C22: =Model_SMR_CfD!J138 -> 1.3540221 | D22: =Model_SMR_CfD!O138 -> 47.697388 | E22: =Model_SMR_CfD!T138 -> 47.697388 | F22: =Model_SMR_CfD!Y138 -> 60.956232 | G22: =Model_SMR_CfD!AD138 -> 91.754744 | H22: =Model_SMR_CfD!AI138 -> 89.007018 | I22: =Model_SMR_CfD!AN138 -> 93.764095 | J22: =Model_SMR_CfD!AS138 -> 96.516202 | K22: =Model_SMR_CfD!AX138 -> 93.764848
B24: SMR · fixed price = last-12-month average spot — post-tax FCF | C24: =Model_SMR_Fixed!J99 -> -1948.2073 | D24: =Model_SMR_Fixed!O99 -> 681.44558 | E24: =Model_SMR_Fixed!T99 -> 748.74132 | F24: =Model_SMR_Fixed!Y99 -> 716.73487 | G24: =Model_SMR_Fixed!AD99 -> 730.80081 | H24: =Model_SMR_Fixed!AI99 -> 634.55416 | I24: =Model_SMR_Fixed!AN99 -> 618.42672 | J24: =Model_SMR_Fixed!AS99 -> 653.4698 | K24: =Model_SMR_Fixed!AX99 -> 618.42672
B25: SMR · fixed price = last-12-month average spot — revenue | C25: =Model_SMR_Fixed!J66 -> 0 | D25: =Model_SMR_Fixed!O66 -> 1194.128 | E25: =Model_SMR_Fixed!T66 -> 1181.5985 | F25: =Model_SMR_Fixed!Y66 -> 1181.5985 | G25: =Model_SMR_Fixed!AD66 -> 1232.2385 | H25: =Model_SMR_Fixed!AI66 -> 1181.5985 | I25: =Model_SMR_Fixed!AN66 -> 1181.5985 | J25: =Model_SMR_Fixed!AS66 -> 1232.2385 | K25: =Model_SMR_Fixed!AX66 -> 1181.5985
B26: SMR · fixed price = last-12-month average spot — local gov. revenue | C26: =Model_SMR_Fixed!J135 -> 1.3540221 | D26: =Model_SMR_Fixed!O135 -> 47.697388 | E26: =Model_SMR_Fixed!T135 -> 47.697388 | F26: =Model_SMR_Fixed!Y135 -> 57.130871 | G26: =Model_SMR_Fixed!AD135 -> 65.736336 | H26: =Model_SMR_Fixed!AI135 -> 81.352553 | I26: =Model_SMR_Fixed!AN135 -> 86.105903 | J26: =Model_SMR_Fixed!AS135 -> 88.528634 | K26: =Model_SMR_Fixed!AX135 -> 86.105903
B28: SMR · merchant, dynamic 50–100 % dispatch — post-tax FCF | C28: =Model_SMR_Dynamic!J98 -> -1948.2073 | D28: =Model_SMR_Dynamic!O98 -> 473.065 | E28: =Model_SMR_Dynamic!T98 -> 514.53907 | F28: =Model_SMR_Dynamic!Y98 -> 493.88482 | G28: =Model_SMR_Dynamic!AD98 -> 491.78984 | H28: =Model_SMR_Dynamic!AI98 -> 457.86659 | I28: =Model_SMR_Dynamic!AN98 -> 449.7651 | J28: =Model_SMR_Dynamic!AS98 -> 483.99276 | K28: =Model_SMR_Dynamic!AX98 -> 409.14574
B29: SMR · merchant, dynamic 50–100 % dispatch — revenue | C29: =Model_SMR_Dynamic!J65 -> 0 | D29: =Model_SMR_Dynamic!O65 -> 979.13023 | E29: =Model_SMR_Dynamic!T65 -> 939.64688 | F29: =Model_SMR_Dynamic!Y65 -> 927.49534 | G29: =Model_SMR_Dynamic!AD65 -> 960.02762 | H29: =Model_SMR_Dynamic!AI65 -> 915.19418 | I29: =Model_SMR_Dynamic!AN65 -> 915.05353 | J29: =Model_SMR_Dynamic!AS65 -> 960.13668 | K29: =Model_SMR_Dynamic!AX65 -> 915.04427
B30: SMR · merchant, dynamic 50–100 % dispatch — local gov. revenue | C30: =Model_SMR_Dynamic!J134 -> 1.3540221 | D30: =Model_SMR_Dynamic!O134 -> 47.697388 | E30: =Model_SMR_Dynamic!T134 -> 47.697388 | F30: =Model_SMR_Dynamic!Y134 -> 50.236063 | G30: =Model_SMR_Dynamic!AD134 -> 58.341521 | H30: =Model_SMR_Dynamic!AI134 -> 57.291963 | I30: =Model_SMR_Dynamic!AN134 -> 59.667469 | J30: =Model_SMR_Dynamic!AS134 -> 60.726446 | K30: =Model_SMR_Dynamic!AX134 -> 71.637094
B32: CCGT 1+1 ~300 MW · merchant dynamic — post-tax FCF | C32: =Model_CCGT!J97 -> -245.625 | D32: =Model_CCGT!O97 -> 17.263541 | E32: =Model_CCGT!T97 -> 1.8122454 | F32: =Model_CCGT!Y97 -> -1.3408349 | G32: =Model_CCGT!AD97 -> -4.1867527 | H32: =Model_CCGT!AI97 -> -3.7376429 | I32: =Model_CCGT!AN97 -> -96.212029 | J32: =Model_CCGT!AS97 -> 0 | K32: =Model_CCGT!AX97 -> 0
B33: CCGT 1+1 ~300 MW · merchant dynamic — revenue | C33: =Model_CCGT!J63 -> 0 | D33: =Model_CCGT!O63 -> 359.67566 | E33: =Model_CCGT!T63 -> 273.23157 | F33: =Model_CCGT!Y63 -> 255.78964 | G33: =Model_CCGT!AD63 -> 246.78946 | H33: =Model_CCGT!AI63 -> 249.22923 | I33: =Model_CCGT!AN63 -> 256.74324 | J33: =Model_CCGT!AS63 -> 0 | K33: =Model_CCGT!AX63 -> 0
B34: CCGT 1+1 ~300 MW · merchant dynamic — local gov. revenue | C34: =Model_CCGT!J133 -> 0.17473725 | D34: =Model_CCGT!O133 -> 6.0621583 | E34: =Model_CCGT!T133 -> 6.0621583 | F34: =Model_CCGT!Y133 -> 6.0621583 | G34: =Model_CCGT!AD133 -> 6.0621583 | H34: =Model_CCGT!AI133 -> 6.0621583 | I34: =Model_CCGT!AN133 -> 6.0621583 | J34: =Model_CCGT!AS133 -> 0 | K34: =Model_CCGT!AX133 -> 0
B36: OCGT 2×150 MW · merchant dynamic — post-tax FCF | C36: =Model_OCGT!J97 -> -675 | D36: =Model_OCGT!O97 -> 9.6453976 | E36: =Model_OCGT!T97 -> 4.9058037 | F36: =Model_OCGT!Y97 -> 3.6831206 | G36: =Model_OCGT!AD97 -> 2.5664885 | H36: =Model_OCGT!AI97 -> 2.5690681 | I36: =Model_OCGT!AN97 -> -48.41191 | J36: =Model_OCGT!AS97 -> 0 | K36: =Model_OCGT!AX97 -> 0
B37: OCGT 2×150 MW · merchant dynamic — revenue | C37: =Model_OCGT!J63 -> 0 | D37: =Model_OCGT!O63 -> 121.15856 | E37: =Model_OCGT!T63 -> 103.19991 | F37: =Model_OCGT!Y63 -> 99.267437 | G37: =Model_OCGT!AD63 -> 95.58837 | H37: =Model_OCGT!AI63 -> 95.571413 | I37: =Model_OCGT!AN63 -> 95.782062 | J37: =Model_OCGT!AS63 -> 0 | K37: =Model_OCGT!AX63 -> 0
B38: OCGT 2×150 MW · merchant dynamic — local gov. revenue | C38: =Model_OCGT!J133 -> 0.6290541 | D38: =Model_OCGT!O133 -> 2.5685396 | E38: =Model_OCGT!T133 -> 2.5685396 | F38: =Model_OCGT!Y133 -> 2.5685396 | G38: =Model_OCGT!AD133 -> 2.5685396 | H38: =Model_OCGT!AI133 -> 2.5685396 | I38: =Model_OCGT!AN133 -> 2.5685396 | J38: =Model_OCGT!AS133 -> 0 | K38: =Model_OCGT!AX133 -> 0
B40: Gas engines 4×76.5 MW · merchant dynamic — post-tax FCF | C40: =Model_Engines!J97 -> -179.28 | D40: =Model_Engines!O97 -> 6.9243515 | E40: =Model_Engines!T97 -> 4.6756388 | F40: =Model_Engines!Y97 -> 4.1875726 | G40: =Model_Engines!AD97 -> 3.5670596 | H40: =Model_Engines!AI97 -> -9.9261317 | I40: =Model_Engines!AN97 -> 0 | J40: =Model_Engines!AS97 -> 0 | K40: =Model_Engines!AX97 -> 0
B41: Gas engines 4×76.5 MW · merchant dynamic — revenue | C41: =Model_Engines!J63 -> 0 | D41: =Model_Engines!O63 -> 56.539946 | E41: =Model_Engines!T63 -> 46.002682 | F41: =Model_Engines!Y63 -> 44.468138 | G41: =Model_Engines!AD63 -> 42.613899 | H41: =Model_Engines!AI63 -> 43.059604 | I41: =Model_Engines!AN63 -> 0 | J41: =Model_Engines!AS63 -> 0 | K41: =Model_Engines!AX63 -> 0
B42: Gas engines 4×76.5 MW · merchant dynamic — local gov. revenue | C42: =Model_Engines!J133 -> 0.15097298 | D42: =Model_Engines!O133 -> 0.77717957 | E42: =Model_Engines!T133 -> 0.77717957 | F42: =Model_Engines!Y133 -> 0.77717957 | G42: =Model_Engines!AD133 -> 0.82282914 | H42: =Model_Engines!AI133 -> 0.77717957 | I42: =Model_Engines!AN133 -> 0 | J42: =Model_Engines!AS133 -> 0 | K42: =Model_Engines!AX133 -> 0

Sheet Input
B2: Input
B3: Blue = hard-coded assumption (edit LOW / CENTRAL / HIGH); green-shaded column H = value selected by the case switch on Dashboard!C4. Money in real PLN, 2026 price level.
B5: # | C5: Parameter | D5: Unit | E5: LOW | F5: CENTRAL | G5: HIGH | H5: Selected | I5: Source / note
B8: 1. Model set-up
C9: Price base year (real terms) | D9: year | E9: 2026 | F9: 2026 | G9: 2026 | H9: =INDEX(E9:G9,1,Dashboard!$C$4) -> 2026 | I9: All money real PLN at 2026 level
C10: EUR/PLN | D10: PLN | E10: 4.3633 | F10: 4.3633 | G10: 4.3633 | H10: =INDEX(E10:G10,1,Dashboard!$C$4) -> 4.3633 | I10: NBP table A mid, 18 Sep 2026 (4.3633)
C11: USD/PLN | D11: PLN | E11: 3.7998 | F11: 3.7998 | G11: 3.7998 | H11: =INDEX(E11:G11,1,Dashboard!$C$4) -> 3.7998 | I11: NBP table A mid, 18 Sep 2026
C12: Hours per year | D12: h | E12: 8760 | F12: 8760 | G12: 8760 | H12: =INDEX(E12:G12,1,Dashboard!$C$4) -> 8760
B14: 2. Macro and cost of capital
C15: Real post-tax WACC — SMR with CfD | D15: % | E15: 0.04 | F15: 0.05 | G15: 0.065 | H15: =INDEX(E15:G15,1,Dashboard!$C$4) -> 0.05 | I15: PEJ EC decision (OJ C 2025/1389) Table 1: nominal 6–8 % with aid; deflated at 2.5 % CPI
C16: Real post-tax WACC — SMR merchant | D16: % | E16: 0.06 | F16: 0.07 | G16: 0.085 | H16: =INDEX(E16:G16,1,Dashboard!$C$4) -> 0.07 | I16: PEJ Table 1 without aid: 8.5–10.5 % nominal
C17: Real post-tax WACC — gas | D17: % | E17: 0.06 | F17: 0.07 | G17: 0.085 | H17: =INDEX(E17:G17,1,Dashboard!$C$4) -> 0.07 | I17: Ministry of Climate LCOE note 7 % real (70 % debt @6 %, 30 % equity @9.5 %)
C18: CPI long run (memo, for nominal conversions) | D18: % | E18: 0.025 | F18: 0.025 | G18: 0.025 | H18: =INDEX(E18:G18,1,Dashboard!$C$4) -> 0.025 | I18: NBP target 2.5 %
B20: 3. Market — Polish day-ahead market (TGE RDN / SDAC), gas, CO2, capacity
C21: Reference year mean day-ahead price (Sep 2025–Aug 2026, hourly PSE/TGE data) | D21: PLN/MWh | E21: 483.39 | F21: 483.39 | G21: 483.39 | H21: =INDEX(E21:G21,1,Dashboard!$C$4) -> 483.39 | I21: PSE csdac-pln API, 8,760 hourly values; TGE 2025 vol.-weighted 446.30
C22: Fixed price for SMR-fixed scenario (= reference mean unless overridden) | D22: PLN/MWh | E22: 483.39 | F22: 483.39 | G22: 483.39 | H22: =INDEX(E22:G22,1,Dashboard!$C$4) -> 483.39 | I22: Scenario S1b: 'average spot over the last year'
C23: Capacity-market price (successor mechanism, if any) | D23: PLN/kW-yr | E23: 0 | F23: 0 | G23: 400 | H23: =INDEX(E23:G23,1,Dashboard!$C$4) -> 0 | I23: 2030 main auction cleared 465.02 PLN/kW-yr (URE, 11 Dec 2025); no auction exists for delivery ≥2031 → 0 in base
C24: Capacity contract length | D24: years | E24: 17 | F24: 17 | G24: 17 | H24: =INDEX(E24:G24,1,Dashboard!$C$4) -> 17 | I24: 17 y new low-emission; 15 y new gas
C25: De-rating factor nuclear (KWD) | D25: # | E25: 0.9383 | F25: 0.9383 | G25: 0.9383 | H25: =INDEX(E25:G25,1,Dashboard!$C$4) -> 0.9383 | I25: Dz.U. 2025 poz. 1066 (2030 auction parameters)
C26: De-rating factor CCGT | D26: # | E26: 0.9315 | F26: 0.9315 | G26: 0.9315 | H26: =INDEX(E26:G26,1,Dashboard!$C$4) -> 0.9315 | I26: same
C27: De-rating factor OCGT / engines | D27: # | E27: 0.9328 | F27: 0.9328 | G27: 0.9328 | H27: =INDEX(E27:G27,1,Dashboard!$C$4) -> 0.9328 | I27: same
C28: Balancing-capacity revenue CCGT | D28: PLN/kW-yr | E28: 0 | F28: 15 | G28: 40 | H28: =INDEX(E28:G28,1,Dashboard!$C$4) -> 15 | I28: aFRR/mFRR 2025 ~180 PLN/MW/h falling to 50–90 by 2027; low contracted share
C29: Balancing-capacity revenue OCGT / engines | D29: PLN/kW-yr | E29: 10 | F29: 40 | G29: 120 | H29: =INDEX(E29:G29,1,Dashboard!$C$4) -> 40 | I29: mFRR/RR from standstill
C30: CO2 emission factor natural gas | D30: t/MWh_th | E30: 0.2006 | F30: 0.2006 | G30: 0.2006 | H30: =INDEX(E30:G30,1,Dashboard!$C$4) -> 0.2006 | I30: KOBiZE 2025 ETS factor 55.73 kg/GJ
C31: URE licence fee (share of revenue) | D31: % | E31: 0.005 | F31: 0.005 | G31: 0.005 | H31: =INDEX(E31:G31,1,Dashboard!$C$4) -> 0.005 | I31: Proposal from 2027: 0.5 % uncapped (current 0.05 %, cap 2.5 m PLN)
C32: Annual mean day-ahead price path (real 2026) | D32: PLN/MWh | I32: 2027–29 TGE BASE_Y forwards (Aug-2026 VWAP 495.5/444.5/420.1); 2030+ judgement bridging TGE 2029 and PEJ counterfactual; hourly shape from the twin | J32: 2027 | K32: 2028 | L32: 2029 | M32: 2030 | N32: 2031 | O32: 2032 | P32: 2033 | Q32: 2034 | R32: 2035 | S32: 2036 | T32: 2037 | U32: 2038 | V32: 2039 | W32: 2040 | X32: 2041 | Y32: 2042 | Z32: 2043 | AA32: 2044 | AB32: 2045 | AC32: 2046 | AD32: 2047 | AE32: 2048 | AF32: 2049 | AG32: 2050 | AH32: 2051 | AI32: 2052 | AJ32: 2053 | AK32: 2054 | AL32: 2055 | AM32: 2056 | AN32: 2057 | AO32: 2058 | AP32: 2059 | AQ32: 2060 | AR32: 2061 | AS32: 2062 | AT32: 2063 | AU32: 2064 | AV32: 2065 | AW32: 2066 | AX32: 2067 | AY32: 2068 | AZ32: 2069 | BA32: 2070 | BB32: 2071 | BC32: 2072 | BD32: 2073 | BE32: 2074 | BF32: 2075 | BG32: 2076 | BH32: 2077 | BI32: 2078 | BJ32: 2079 | BK32: 2080 | BL32: 2081 | BM32: 2082 | BN32: 2083 | BO32: 2084 | BP32: 2085 | BQ32: 2086 | BR32: 2087 | BS32: 2088 | BT32: 2089 | BU32: 2090 | BV32: 2091 | BW32: 2092 | BX32: 2093 | BY32: 2094 | BZ32: 2095 | CA32: 2096
C33: LOW | J33: 440 | K33: 380 | L33: 350 | M33: 320 | N33: 316 | O33: 312 | P33: 308 | Q33: 304 | R33: 300 | S33: 298 | T33: 296 | U33: 294 | V33: 292 | W33: 290 | X33: 289 | Y33: 288 | Z33: 287 | AA33: 286 | AB33: 285 | AC33: 284 | AD33: 283 | AE33: 282 | AF33: 281 | AG33: 280 | AH33: 280 | AI33: 280 | AJ33: 280 | AK33: 280 | AL33: 280 | AM33: 280 | AN33: 280 | AO33: 280 | AP33: 280 | AQ33: 280 | AR33: 280 | AS33: 280 | AT33: 280 | AU33: 280 | AV33: 280 | AW33: 280 | AX33: 280 | AY33: 280 | AZ33: 280 | BA33: 280 | BB33: 280 | BC33: 280 | BD33: 280 | BE33: 280 | BF33: 280 | BG33: 280 | BH33: 280 | BI33: 280 | BJ33: 280 | BK33: 280 | BL33: 280 | BM33: 280 | BN33: 280 | BO33: 280 | BP33: 280 | BQ33: 280 | BR33: 280 | BS33: 280 | BT33: 280 | BU33: 280 | BV33: 280 | BW33: 280 | BX33: 280 | BY33: 280 | BZ33: 280 | CA33: 280
C34: CENTRAL | J34: 496 | K34: 445 | L34: 420 | M34: 410 | N34: 408 | O34: 406 | P34: 404 | Q34: 402 | R34: 400 | S34: 398 | T34: 396 | U34: 394 | V34: 392 | W34: 390 | X34: 389 | Y34: 388 | Z34: 387 | AA34: 386 | AB34: 385 | AC34: 384 | AD34: 383 | AE34: 382 | AF34: 381 | AG34: 380 | AH34: 380 | AI34: 380 | AJ34: 380 | AK34: 380 | AL34: 380 | AM34: 380 | AN34: 380 | AO34: 380 | AP34: 380 | AQ34: 380 | AR34: 380 | AS34: 380 | AT34: 380 | AU34: 380 | AV34: 380 | AW34: 380 | AX34: 380 | AY34: 380 | AZ34: 380 | BA34: 380 | BB34: 380 | BC34: 380 | BD34: 380 | BE34: 380 | BF34: 380 | BG34: 380 | BH34: 380 | BI34: 380 | BJ34: 380 | BK34: 380 | BL34: 380 | BM34: 380 | BN34: 380 | BO34: 380 | BP34: 380 | BQ34: 380 | BR34: 380 | BS34: 380 | BT34: 380 | BU34: 380 | BV34: 380 | BW34: 380 | BX34: 380 | BY34: 380 | BZ34: 380 | CA34: 380
C35: HIGH | J35: 590 | K35: 520 | L35: 480 | M35: 470 | N35: 472 | O35: 474 | P35: 476 | Q35: 478 | R35: 480 | S35: 484 | T35: 488 | U35: 492 | V35: 496 | W35: 500 | X35: 502 | Y35: 504 | Z35: 506 | AA35: 508 | AB35: 510 | AC35: 512 | AD35: 514 | AE35: 516 | AF35: 518 | AG35: 520 | AH35: 520 | AI35: 520 | AJ35: 520 | AK35: 520 | AL35: 520 | AM35: 520 | AN35: 520 | AO35: 520 | AP35: 520 | AQ35: 520 | AR35: 520 | AS35: 520 | AT35: 520 | AU35: 520 | AV35: 520 | AW35: 520 | AX35: 520 | AY35: 520 | AZ35: 520 | BA35: 520 | BB35: 520 | BC35: 520 | BD35: 520 | BE35: 520 | BF35: 520 | BG35: 520 | BH35: 520 | BI35: 520 | BJ35: 520 | BK35: 520 | BL35: 520 | BM35: 520 | BN35: 520 | BO35: 520 | BP35: 520 | BQ35: 520 | BR35: 520 | BS35: 520 | BT35: 520 | BU35: 520 | BV35: 520 | BW35: 520 | BX35: 520 | BY35: 520 | BZ35: 520 | CA35: 520
C36: Selected | J36: =CHOOSE(Dashboard!$C$4,J33,J34,J35) -> 496 | K36: =CHOOSE(Dashboard!$C$4,K33,K34,K35) -> 445 | L36: =CHOOSE(Dashboard!$C$4,L33,L34,L35) -> 420 | M36: =CHOOSE(Dashboard!$C$4,M33,M34,M35) -> 410 | N36: =CHOOSE(Dashboard!$C$4,N33,N34,N35) -> 408 | O36: =CHOOSE(Dashboard!$C$4,O33,O34,O35) -> 406 | P36: =CHOOSE(Dashboard!$C$4,P33,P34,P35) -> 404 | Q36: =CHOOSE(Dashboard!$C$4,Q33,Q34,Q35) -> 402 | ... CA36: =CHOOSE(Dashboard!$C$4,CA33,CA34,CA35) -> 380
C38: Gas price at PL virtual point (real 2026) | D38: PLN/MWh_th | I38: TGE GAS_BASE_Y-27 Aug-2026 214.20; TTF forward proxy 38/33/31 EUR + 4 EUR PL premium | J38: 2027 | K38: 2028 | L38: 2029 | M38: 2030 | N38: 2031 | O38: 2032 | P38: 2033 | Q38: 2034 | R38: 2035 | S38: 2036 | T38: 2037 | U38: 2038 | V38: 2039 | W38: 2040 | X38: 2041 | Y38: 2042 | Z38: 2043 | AA38: 2044 | AB38: 2045 | AC38: 2046 | AD38: 2047 | AE38: 2048 | AF38: 2049 | AG38: 2050 | AH38: 2051 | AI38: 2052 | AJ38: 2053 | AK38: 2054 | AL38: 2055 | AM38: 2056 | AN38: 2057 | AO38: 2058 | AP38: 2059 | AQ38: 2060 | AR38: 2061 | AS38: 2062 | AT38: 2063 | AU38: 2064 | AV38: 2065 | AW38: 2066 | AX38: 2067 | AY38: 2068 | AZ38: 2069 | BA38: 2070 | BB38: 2071 | BC38: 2072 | BD38: 2073 | BE38: 2074 | BF38: 2075 | BG38: 2076 | BH38: 2077 | BI38: 2078 | BJ38: 2079 | BK38: 2080 | BL38: 2081 | BM38: 2082 | BN38: 2083 | BO38: 2084 | BP38: 2085 | BQ38: 2086 | BR38: 2087 | BS38: 2088 | BT38: 2089 | BU38: 2090 | BV38: 2091 | BW38: 2092 | BX38: 2093 | BY38: 2094 | BZ38: 2095 | CA38: 2096
C39: LOW | J39: 180 | K39: 130 | L39: 115 | M39: 110 | N39: 110 | O39: 110 | P39: 110 | Q39: 110 | R39: 110 | S39: 110 | T39: 110 | U39: 110 | V39: 110 | W39: 110 | X39: 110 | Y39: 110 | Z39: 110 | AA39: 110 | AB39: 110 | AC39: 110 | AD39: 110 | AE39: 110 | AF39: 110 | AG39: 110 | AH39: 110 | AI39: 110 | AJ39: 110 | AK39: 110 | AL39: 110 | AM39: 110 | AN39: 110 | AO39: 110 | AP39: 110 | AQ39: 110 | AR39: 110 | AS39: 110 | AT39: 110 | AU39: 110 | AV39: 110 | AW39: 110 | AX39: 110 | AY39: 110 | AZ39: 110 | BA39: 110 | BB39: 110 | BC39: 110 | BD39: 110 | BE39: 110 | BF39: 110 | BG39: 110 | BH39: 110 | BI39: 110 | BJ39: 110 | BK39: 110 | BL39: 110 | BM39: 110 | BN39: 110 | BO39: 110 | BP39: 110 | BQ39: 110 | BR39: 110 | BS39: 110 | BT39: 110 | BU39: 110 | BV39: 110 | BW39: 110 | BX39: 110 | BY39: 110 | BZ39: 110 | CA39: 110
C40: CENTRAL | J40: 214 | K40: 165 | L40: 145 | M40: 135 | N40: 135 | O40: 135 | P40: 135 | Q40: 135 | R40: 135 | S40: 135 | T40: 135 | U40: 135 | V40: 135 | W40: 135 | X40: 135 | Y40: 135 | Z40: 135 | AA40: 135 | AB40: 135 | AC40: 135 | AD40: 135 | AE40: 135 | AF40: 135 | AG40: 135 | AH40: 135 | AI40: 135 | AJ40: 135 | AK40: 135 | AL40: 135 | AM40: 135 | AN40: 135 | AO40: 135 | AP40: 135 | AQ40: 135 | AR40: 135 | AS40: 135 | AT40: 135 | AU40: 135 | AV40: 135 | AW40: 135 | AX40: 135 | AY40: 135 | AZ40: 135 | BA40: 135 | BB40: 135 | BC40: 135 | BD40: 135 | BE40: 135 | BF40: 135 | BG40: 135 | BH40: 135 | BI40: 135 | BJ40: 135 | BK40: 135 | BL40: 135 | BM40: 135 | BN40: 135 | BO40: 135 | BP40: 135 | BQ40: 135 | BR40: 135 | BS40: 135 | BT40: 135 | BU40: 135 | BV40: 135 | BW40: 135 | BX40: 135 | BY40: 135 | BZ40: 135 | CA40: 135
C41: HIGH | J41: 290 | K41: 200 | L41: 185 | M41: 175 | N41: 175 | O41: 175 | P41: 175 | Q41: 175 | R41: 175 | S41: 175 | T41: 175 | U41: 175 | V41: 175 | W41: 175 | X41: 175 | Y41: 175 | Z41: 175 | AA41: 175 | AB41: 175 | AC41: 175 | AD41: 175 | AE41: 175 | AF41: 175 | AG41: 175 | AH41: 175 | AI41: 175 | AJ41: 175 | AK41: 175 | AL41: 175 | AM41: 175 | AN41: 175 | AO41: 175 | AP41: 175 | AQ41: 175 | AR41: 175 | AS41: 175 | AT41: 175 | AU41: 175 | AV41: 175 | AW41: 175 | AX41: 175 | AY41: 175 | AZ41: 175 | BA41: 175 | BB41: 175 | BC41: 175 | BD41: 175 | BE41: 175 | BF41: 175 | BG41: 175 | BH41: 175 | BI41: 175 | BJ41: 175 | BK41: 175 | BL41: 175 | BM41: 175 | BN41: 175 | BO41: 175 | BP41: 175 | BQ41: 175 | BR41: 175 | BS41: 175 | BT41: 175 | BU41: 175 | BV41: 175 | BW41: 175 | BX41: 175 | BY41: 175 | BZ41: 175 | CA41: 175
C42: Selected | J42: =CHOOSE(Dashboard!$C$4,J39,J40,J41) -> 214 | K42: =CHOOSE(Dashboard!$C$4,K39,K40,K41) -> 165 | L42: =CHOOSE(Dashboard!$C$4,L39,L40,L41) -> 145 | M42: =CHOOSE(Dashboard!$C$4,M39,M40,M41) -> 135 | N42: =CHOOSE(Dashboard!$C$4,N39,N40,N41) -> 135 | O42: =CHOOSE(Dashboard!$C$4,O39,O40,O41) -> 135 | P42: =CHOOSE(Dashboard!$C$4,P39,P40,P41) -> 135 | Q42: =CHOOSE(Dashboard!$C$4,Q39,Q40,Q41) -> 135 | ... CA42: =CHOOSE(Dashboard!$C$4,CA39,CA40,CA41) -> 135
C44: EUA price (real 2026) | D44: EUR/t | I44: Spot 86.9 EUR/t (18 Sep 2026); Reuters poll 2027 93; consensus 2030 126 (80–147) | J44: 2027 | K44: 2028 | L44: 2029 | M44: 2030 | N44: 2031 | O44: 2032 | P44: 2033 | Q44: 2034 | R44: 2035 | S44: 2036 | T44: 2037 | U44: 2038 | V44: 2039 | W44: 2040 | X44: 2041 | Y44: 2042 | Z44: 2043 | AA44: 2044 | AB44: 2045 | AC44: 2046 | AD44: 2047 | AE44: 2048 | AF44: 2049 | AG44: 2050 | AH44: 2051 | AI44: 2052 | AJ44: 2053 | AK44: 2054 | AL44: 2055 | AM44: 2056 | AN44: 2057 | AO44: 2058 | AP44: 2059 | AQ44: 2060 | AR44: 2061 | AS44: 2062 | AT44: 2063 | AU44: 2064 | AV44: 2065 | AW44: 2066 | AX44: 2067 | AY44: 2068 | AZ44: 2069 | BA44: 2070 | BB44: 2071 | BC44: 2072 | BD44: 2073 | BE44: 2074 | BF44: 2075 | BG44: 2076 | BH44: 2077 | BI44: 2078 | BJ44: 2079 | BK44: 2080 | BL44: 2081 | BM44: 2082 | BN44: 2083 | BO44: 2084 | BP44: 2085 | BQ44: 2086 | BR44: 2087 | BS44: 2088 | BT44: 2089 | BU44: 2090 | BV44: 2091 | BW44: 2092 | BX44: 2093 | BY44: 2094 | BZ44: 2095 | CA44: 2096
C45: LOW | J45: 70 | K45: 73.333333 | L45: 76.666667 | M45: 80 | N45: 82 | O45: 84 | P45: 86 | Q45: 88 | R45: 90 | S45: 90 | T45: 90 | U45: 90 | V45: 90 | W45: 90 | X45: 90 | Y45: 90 | Z45: 90 | AA45: 90 | AB45: 90 | AC45: 90 | AD45: 90 | AE45: 90 | AF45: 90 | AG45: 90 | AH45: 90 | AI45: 90 | AJ45: 90 | AK45: 90 | AL45: 90 | AM45: 90 | AN45: 90 | AO45: 90 | AP45: 90 | AQ45: 90 | AR45: 90 | AS45: 90 | AT45: 90 | AU45: 90 | AV45: 90 | AW45: 90 | AX45: 90 | AY45: 90 | AZ45: 90 | BA45: 90 | BB45: 90 | BC45: 90 | BD45: 90 | BE45: 90 | BF45: 90 | BG45: 90 | BH45: 90 | BI45: 90 | BJ45: 90 | BK45: 90 | BL45: 90 | BM45: 90 | BN45: 90 | BO45: 90 | BP45: 90 | BQ45: 90 | BR45: 90 | BS45: 90 | BT45: 90 | BU45: 90 | BV45: 90 | BW45: 90 | BX45: 90 | BY45: 90 | BZ45: 90 | CA45: 90
C46: CENTRAL | J46: 90 | K46: 98.333333 | L46: 106.66667 | M46: 115 | N46: 120 | O46: 125 | P46: 130 | Q46: 135 | R46: 140 | S46: 142 | T46: 144 | U46: 146 | V46: 148 | W46: 150 | X46: 150 | Y46: 150 | Z46: 150 | AA46: 150 | AB46: 150 | AC46: 150 | AD46: 150 | AE46: 150 | AF46: 150 | AG46: 150 | AH46: 150 | AI46: 150 | AJ46: 150 | AK46: 150 | AL46: 150 | AM46: 150 | AN46: 150 | AO46: 150 | AP46: 150 | AQ46: 150 | AR46: 150 | AS46: 150 | AT46: 150 | AU46: 150 | AV46: 150 | AW46: 150 | AX46: 150 | AY46: 150 | AZ46: 150 | BA46: 150 | BB46: 150 | BC46: 150 | BD46: 150 | BE46: 150 | BF46: 150 | BG46: 150 | BH46: 150 | BI46: 150 | BJ46: 150 | BK46: 150 | BL46: 150 | BM46: 150 | BN46: 150 | BO46: 150 | BP46: 150 | BQ46: 150 | BR46: 150 | BS46: 150 | BT46: 150 | BU46: 150 | BV46: 150 | BW46: 150 | BX46: 150 | BY46: 150 | BZ46: 150 | CA46: 150
C47: HIGH | J47: 105 | K47: 118.33333 | L47: 131.66667 | M47: 145 | N47: 156 | O47: 167 | P47: 178 | Q47: 189 | R47: 200 | S47: 204 | T47: 208 | U47: 212 | V47: 216 | W47: 220 | X47: 220 | Y47: 220 | Z47: 220 | AA47: 220 | AB47: 220 | AC47: 220 | AD47: 220 | AE47: 220 | AF47: 220 | AG47: 220 | AH47: 220 | AI47: 220 | AJ47: 220 | AK47: 220 | AL47: 220 | AM47: 220 | AN47: 220 | AO47: 220 | AP47: 220 | AQ47: 220 | AR47: 220 | AS47: 220 | AT47: 220 | AU47: 220 | AV47: 220 | AW47: 220 | AX47: 220 | AY47: 220 | AZ47: 220 | BA47: 220 | BB47: 220 | BC47: 220 | BD47: 220 | BE47: 220 | BF47: 220 | BG47: 220 | BH47: 220 | BI47: 220 | BJ47: 220 | BK47: 220 | BL47: 220 | BM47: 220 | BN47: 220 | BO47: 220 | BP47: 220 | BQ47: 220 | BR47: 220 | BS47: 220 | BT47: 220 | BU47: 220 | BV47: 220 | BW47: 220 | BX47: 220 | BY47: 220 | BZ47: 220 | CA47: 220
C48: Selected | J48: =CHOOSE(Dashboard!$C$4,J45,J46,J47) -> 90 | K48: =CHOOSE(Dashboard!$C$4,K45,K46,K47) -> 98.333333 | L48: =CHOOSE(Dashboard!$C$4,L45,L46,L47) -> 106.66667 | M48: =CHOOSE(Dashboard!$C$4,M45,M46,M47) -> 115 | N48: =CHOOSE(Dashboard!$C$4,N45,N46,N47) -> 120 | O48: =CHOOSE(Dashboard!$C$4,O45,O46,O47) -> 125 | P48: =CHOOSE(Dashboard!$C$4,P45,P46,P47) -> 130 | Q48: =CHOOSE(Dashboard!$C$4,Q45,Q46,Q47) -> 135 | ... CA48: =CHOOSE(Dashboard!$C$4,CA45,CA46,CA47) -> 150
...

Sheet Twin
B1: Twin — outputs of the hourly digital-twin dispatch (Python: smrtwin), per operating year k
B2: cf = capacity factor; capture = generation-weighted price ÷ annual mean price; cfd_ref = generation-weighted CfD reference (daily TGeBase) ÷ annual mean; heat = MWh_th per MWh_e incl. no-load & start fuel; start = start costs (wear) PLN/MWh_e; fuel_ratio = SMR fuel cost ÷ (energy × fuel price). Re-generate with `python build_excel.py` after `python run_all.py`.
C4: operating year k → | G4: 1 | H4: 2 | I4: 3 | J4: 4 | K4: 5 | L4: 6 | M4: 7 | N4: 8 | O4: 9 | P4: 10 | Q4: 11 | R4: 12 | S4: 13 | T4: 14 | U4: 15 | V4: 16 | W4: 17 | X4: 18 | Y4: 19 | Z4: 20 | AA4: 21 | AB4: 22 | AC4: 23 | AD4: 24 | AE4: 25 | AF4: 26 | AG4: 27 | AH4: 28 | AI4: 29 | AJ4: 30 | AK4: 31 | AL4: 32 | AM4: 33 | AN4: 34 | AO4: 35 | AP4: 36 | AQ4: 37 | AR4: 38 | AS4: 39 | AT4: 40 | AU4: 41 | AV4: 42 | AW4: 43 | AX4: 44 | AY4: 45 | AZ4: 46 | BA4: 47 | BB4: 48 | BC4: 49 | BD4: 50 | BE4: 51 | BF4: 52 | BG4: 53 | BH4: 54 | BI4: 55 | BJ4: 56 | BK4: 57 | BL4: 58 | BM4: 59 | BN4: 60
B5: SMR · CfD (two-way, PEJ template)
B6: cf · low | G6: 0.94933505 | H6: 0.91810217 | I6: 0.91810217 | J6: 0.97931279 | K6: 0.94709361 | L6: 0.94709361 | M6: 0.97931279 | N6: 0.94709361 | O6: 0.94709361 | P6: 0.9121895 | Q6: 0.94709361 | R6: 0.94709361 | S6: 0.97931279 | T6: 0.94709361 | U6: 0.94709361 | V6: 0.97931279 | W6: 0.94709361 | X6: 0.94709361 | Y6: 0.97931279 | Z6: 0.89876484 | AA6: 0.94709361 | AB6: 0.97931279 | AC6: 0.94709361 | AD6: 0.94709361 | AE6: 0.97931279 | AF6: 0.94709361 | AG6: 0.94709361 | AH6: 0.97931279 | AI6: 0.94709361 | AJ6: 0.89876484 | AK6: 0.97931279 | AL6: 0.94709361 | AM6: 0.94709361 | AN6: 0.97931279 | AO6: 0.94709361 | AP6: 0.94709361 | AQ6: 0.97931279 | AR6: 0.94706164 | AS6: 0.94706164 | AT6: 0.91215753 | AU6: 0.91140639 | AV6: 0.9113984 | AW6: 0.94352169 | AX6: 0.91130251 | AY6: 0.91119863 | AZ6: 0.94341781 | BA6: 0.91110274 | BB6: 0.91107078 | BC6: 0.94326598 | BD6: 0.86268607 | BE6: 0.91093493 | BF6: 0.94315411 | BG6: 0.91088699 | BH6: 0.910871 | BI6: 0.94309018 | BJ6: 0.91084703 | BK6: 0.91078311 | BL6: 0.94300228 | BM6: 0.91074315 | BN6: 0.86238242
B7: cf · central | G7: 0.92592856 | H7: 0.88778905 | I7: 0.88778905 | J7: 0.95559225 | K7: 0.91623184 | L7: 0.91624706 | M7: 0.95563172 | N7: 0.91623184 | O7: 0.91625609 | P7: 0.88999965 | Q7: 0.91628034 | R7: 0.91628034 | S7: 0.95564074 | T7: 0.91629556 | U7: 0.91635026 | V7: 0.95570447 | W7: 0.91626511 | X7: 0.91626511 | Y7: 0.95562552 | Z7: 0.8768562 | AA7: 0.91626511 | AB7: 0.95561029 | AC7: 0.91622563 | AD7: 0.91620139 | AE7: 0.95558604 | AF7: 0.91620139 | AG7: 0.91620139 | AH7: 0.95558604 | AI7: 0.91620139 | AJ7: 0.87681673 | AK7: 0.95558604 | AL7: 0.91620139 | AM7: 0.91620139 | AN7: 0.95558604 | AO7: 0.91620139 | AP7: 0.91620139 | AQ7: 0.95558604 | AR7: 0.91620139 | AS7: 0.91620139 | AT7: 0.88994495 | AU7: 0.88226201 | AV7: 0.88226201 | AW7: 0.92164666 | AX7: 0.88226201 | AY7: 0.88226201 | AZ7: 0.92164666 | BA7: 0.88226201 | BB7: 0.88226201 | BC7: 0.92164666 | BD7: 0.84287735 | BE7: 0.88226201 | BF7: 0.92164666 | BG7: 0.88226201 | BH7: 0.88226201 | BI7: 0.92164666 | BJ7: 0.88226201 | BK7: 0.88226201 | BL7: 0.92164666 | BM7: 0.88226201 | BN7: 0.84287735
B8: cf · high | G8: 0.89770461 | H8: 0.84808148 | I8: 0.84783872 | J8: 0.92633493 | K8: 0.875173 | L8: 0.87489612 | M8: 0.92573642 | N8: 0.87452414 | O8: 0.87425006 | P8: 0.86139315 | Q8: 0.87362917 | R8: 0.87332991 | S8: 0.92418139 | T8: 0.8730726 | U8: 0.87299429 | V8: 0.92392968 | W8: 0.87291598 | X8: 0.87291598 | Y8: 0.92392968 | Z8: 0.84740913 | AA8: 0.87291598 | AB8: 0.92392968 | AC8: 0.87291598 | AD8: 0.87291598 | AE8: 0.92392968 | AF8: 0.87291598 | AG8: 0.87291598 | AH8: 0.92392968 | AI8: 0.87291598 | AJ8: 0.84740913 | AK8: 0.92392968 | AL8: 0.87291598 | AM8: 0.87291598 | AN8: 0.92392968 | AO8: 0.87291598 | AP8: 0.87291598 | AQ8: 0.92392968 | AR8: 0.87291598 | AS8: 0.87291598 | AT8: 0.86016256 | AU8: 0.84580097 | AV8: 0.84580097 | AW8: 0.89681467 | AX8: 0.84580097 | AY8: 0.84580097 | AZ8: 0.89681467 | BA8: 0.84580097 | BB8: 0.84580097 | BC8: 0.89681467 | BD8: 0.82029412 | BE8: 0.84580097 | BF8: 0.89681467 | BG8: 0.84580097 | BH8: 0.84580097 | BI8: 0.89681467 | BJ8: 0.84580097 | BK8: 0.84580097 | BL8: 0.89681467 | BM8: 0.84580097 | BN8: 0.82029412
B9: cf · selected | G9: =CHOOSE(Dashboard!$C$4,G6,G7,G8) -> 0.92592856 | H9: =CHOOSE(Dashboard!$C$4,H6,H7,H8) -> 0.88778905 | I9: =CHOOSE(Dashboard!$C$4,I6,I7,I8) -> 0.88778905 | J9: =CHOOSE(Dashboard!$C$4,J6,J7,J8) -> 0.95559225 | K9: =CHOOSE(Dashboard!$C$4,K6,K7,K8) -> 0.91623184 | L9: =CHOOSE(Dashboard!$C$4,L6,L7,L8) -> 0.91624706 | M9: =CHOOSE(Dashboard!$C$4,M6,M7,M8) -> 0.95563172 | N9: =CHOOSE(Dashboard!$C$4,N6,N7,N8) -> 0.91623184 | ... BN9: =CHOOSE(Dashboard!$C$4,BN6,BN7,BN8) -> 0.84287735
B10: capture · low | G10: 1.0024088 | H10: 0.99699465 | I10: 0.99698633 | J10: 1.0024283 | K10: 0.99697014 | L10: 0.99696182 | M10: 1.0024472 | N10: 0.99694518 | O10: 0.99693686 | P10: 0.9970233 | Q10: 0.99692021 | R10: 0.99691189 | S10: 1.0024852 | T10: 0.99689525 | U10: 0.99688692 | V10: 1.0025042 | W10: 0.99687028 | X10: 0.99686196 | Y10: 1.0025232 | Z10: 0.99886423 | AA10: 0.99683699 | AB10: 1.0025422 | AC10: 0.99682035 | AD10: 0.99681203 | AE10: 1.0025612 | AF10: 0.99679538 | AG10: 0.99678706 | AH10: 1.0025802 | AI10: 0.99677042 | AJ10: 0.99850523 | AK10: 1.0025992 | AL10: 0.99674545 | AM10: 0.99673713 | AN10: 1.0026181 | AO10: 0.99672049 | AP10: 0.99671217 | AQ10: 1.0026371 | AR10: 0.99678527 | AS10: 0.99677713 | AT10: 0.9962905 | AU10: 1.0369517 | AV10: 1.0369582 | AW10: 1.0419184 | AX10: 1.0370473 | AY10: 1.037145 | AZ10: 1.0420564 | BA10: 1.0372343 | BB10: 1.0372639 | BC10: 1.042239 | BD10: 1.0408382 | BE10: 1.0373909 | BF10: 1.0423851 | BG10: 1.0374353 | BH10: 1.0374499 | BI10: 1.0424873 | BJ10: 1.0374717 | BK10: 1.037532 | BL10: 1.042612 | BM10: 1.0375692 | BN10: 1.0408562
B11: capture · central | G11: 1.004328 | H11: 0.99915641 | I11: 0.99913388 | J11: 1.0043053 | K11: 0.999041 | L11: 0.99899338 | M11: 1.0043079 | N11: 0.99897341 | O11: 0.99893284 | P11: 0.99842585 | Q11: 0.99888776 | R11: 0.99886518 | S11: 1.0044656 | T11: 0.99887961 | U11: 0.9987474 | V11: 1.0044792 | W11: 0.99887485 | X11: 0.99890302 | Y11: 1.0046999 | Z11: 1.0000376 | AA11: 0.99887169 | AB11: 1.0048173 | AC11: 0.9988998 | AD11: 0.99893464 | AE11: 1.0049212 | AF11: 0.99889208 | AG11: 0.9988708 | AH11: 1.0049546 | AI11: 0.9988708 | AJ11: 0.99969665 | AK11: 1.0049546 | AL11: 0.9988708 | AM11: 0.9988708 | AN11: 1.0049546 | AO11: 0.9988708 | AP11: 0.9988708 | AQ11: 1.0049546 | AR11: 0.9988708 | AS11: 0.9988708 | AT11: 0.9978925 | AU11: 1.0385695 | AV11: 1.0385695 | AW11: 1.043181 | AX11: 1.0385695 | AY11: 1.0385695 | AZ11: 1.043181 | BA11: 1.0385695 | BB11: 1.0385695 | BC11: 1.043181 | BD11: 1.0412836 | BE11: 1.0385695 | BF11: 1.043181 | BG11: 1.0385695 | BH11: 1.0385695 | BI11: 1.043181 | BJ11: 1.0385695 | BK11: 1.0385695 | BL11: 1.043181 | BM11: 1.0385695 | BN11: 1.0412836
B12: capture · high | G12: 1.0058105 | H12: 1.0002075 | I12: 1.0004661 | J12: 1.0067031 | K12: 1.0007996 | L12: 1.0010516 | M12: 1.0074073 | N12: 1.0013918 | O12: 1.0016354 | P12: 1.001818 | Q12: 1.0021608 | R12: 1.0024804 | S12: 1.0092088 | T12: 1.0026763 | U12: 1.0026872 | V12: 1.0095124 | W12: 1.0027429 | X12: 1.0027429 | Y12: 1.0095124 | Z12: 1.0046388 | AA12: 1.0027429 | AB12: 1.0095124 | AC12: 1.0027429 | AD12: 1.0027429 | AE12: 1.0095124 | AF12: 1.0027429 | AG12: 1.0027429 | AH12: 1.0095124 | AI12: 1.0027429 | AJ12: 1.0046388 | AK12: 1.0095124 | AL12: 1.0027429 | AM12: 1.0027429 | AN12: 1.0095124 | AO12: 1.0027429 | AP12: 1.0027429 | AQ12: 1.0095124 | AR12: 1.0027429 | AS12: 1.0027429 | AT12: 1.0027522 | AU12: 1.0366849 | AV12: 1.0366849 | AW12: 1.0417284 | AX12: 1.0366849 | AY12: 1.0366849 | AZ12: 1.0417284 | BA12: 1.0366849 | BB12: 1.0366849 | BC12: 1.0417284 | BD12: 1.0396989 | BE12: 1.0366849 | BF12: 1.0417284 | BG12: 1.0366849 | BH12: 1.0366849 | BI12: 1.0417284 | BJ12: 1.0366849 | BK12: 1.0366849 | BL12: 1.0417284 | BM12: 1.0366849 | BN12: 1.0396989
B13: capture · selected | G13: =CHOOSE(Dashboard!$C$4,G10,G11,G12) -> 1.004328 | H13: =CHOOSE(Dashboard!$C$4,H10,H11,H12) -> 0.99915641 | I13: =CHOOSE(Dashboard!$C$4,I10,I11,I12) -> 0.99913388 | J13: =CHOOSE(Dashboard!$C$4,J10,J11,J12) -> 1.0043053 | K13: =CHOOSE(Dashboard!$C$4,K10,K11,K12) -> 0.999041 | L13: =CHOOSE(Dashboard!$C$4,L10,L11,L12) -> 0.99899338 | M13: =CHOOSE(Dashboard!$C$4,M10,M11,M12) -> 1.0043079 | N13: =CHOOSE(Dashboard!$C$4,N10,N11,N12) -> 0.99897341 | ... BN13: =CHOOSE(Dashboard!$C$4,BN10,BN11,BN12) -> 1.0412836
B14: cfd_ref · low | G14: 1.0006452 | H14: 0.99516523 | I14: 0.99515113 | J14: 1.0006492 | K14: 0.99512474 | L14: 0.99511064 | M14: 1.0006514 | N14: 0.99508245 | O14: 0.99506835 | P14: 0.99507729 | Q14: 0.99504015 | R14: 0.99502605 | S14: 1.0006558 | T14: 0.99499785 | U14: 0.99498375 | V14: 1.0006581 | W14: 0.99495555 | X14: 0.99494145 | Y14: 1.0006603 | Z14: 0.99682827 | AA14: 0.99489916 | AB14: 1.0006625 | AC14: 0.99487096 | AD14: 0.99485686 | AE14: 1.0006647 | AF14: 0.99482866 | AG14: 0.99481456 | AH14: 1.000667 | AI14: 0.99478636 | AJ14: 0.9964084 | AK14: 1.0006692 | AL14: 0.99474407 | AM14: 0.99472997 | AN14: 1.0006714 | AO14: 0.99470177 | AP14: 0.99468767 | AQ14: 1.0006737 | AR14: 0.99469445 | AS14: 0.99468037 | AT14: 0.99410733 | AU14: 1 | AV14: 1 | AW14: 1 | AX14: 1 | AY14: 1 | AZ14: 1 | BA14: 1 | BB14: 1 | BC14: 1 | BD14: 1 | BE14: 1 | BF14: 1 | BG14: 1 | BH14: 1 | BI14: 1 | BJ14: 1 | BK14: 1 | BL14: 1 | BM14: 1 | BN14: 1
B15: cfd_ref · central | G15: 0.99940571 | H15: 0.99404549 | I15: 0.99400945 | J15: 0.99949249 | K15: 0.99404005 | L15: 0.99399973 | M15: 0.9995071 | N15: 0.99393184 | O15: 0.99391051 | P15: 0.99324149 | Q15: 0.99387142 | R15: 0.9938353 | S15: 0.99959832 | T15: 0.99384431 | U15: 0.99377337 | V15: 0.99965641 | W15: 0.99375544 | X15: 0.99376941 | Y15: 0.99973209 | Z15: 0.99460852 | AA15: 0.99369497 | AB15: 0.99978789 | AC15: 0.99363961 | AD15: 0.99362639 | AE15: 0.99981758 | AF15: 0.99355428 | AG15: 0.99351823 | AH15: 0.99982268 | AI15: 0.99351823 | AJ15: 0.99410365 | AK15: 0.99982268 | AL15: 0.99351823 | AM15: 0.99351823 | AN15: 0.99982268 | AO15: 0.99351823 | AP15: 0.99351823 | AQ15: 0.99982268 | AR15: 0.99351823 | AS15: 0.99351823 | AT15: 0.99238201 | AU15: 1 | AV15: 1 | AW15: 1 | AX15: 1 | AY15: 1 | AZ15: 1 | BA15: 1 | BB15: 1 | BC15: 1 | BD15: 1 | BE15: 1 | BF15: 1 | BG15: 1 | BH15: 1 | BI15: 1 | BJ15: 1 | BK15: 1 | BL15: 1 | BM15: 1 | BN15: 1
B16: cfd_ref · high | G16: 0.99934274 | H16: 0.99306444 | I16: 0.9929917 | J16: 0.999442 | K16: 0.99291006 | L16: 0.99281041 | M16: 0.99940405 | N16: 0.99265976 | O16: 0.99255769 | P16: 0.99245309 | Q16: 0.99230311 | R16: 0.99223957 | S16: 0.99932962 | T16: 0.99208177 | U16: 0.99197303 | V16: 0.99929603 | W16: 0.99192947 | X16: 0.99192947 | Y16: 0.99929603 | Z16: 0.99349992 | AA16: 0.99192947 | AB16: 0.99929603 | AC16: 0.99192947 | AD16: 0.99192947 | AE16: 0.99929603 | AF16: 0.99192947 | AG16: 0.99192947 | AH16: 0.99929603 | AI16: 0.99192947 | AJ16: 0.99349992 | AK16: 0.99929603 | AL16: 0.99192947 | AM16: 0.99192947 | AN16: 0.99929603 | AO16: 0.99192947 | AP16: 0.99192947 | AQ16: 0.99929603 | AR16: 0.99192947 | AS16: 0.99192947 | AT16: 0.99177847 | AU16: 1 | AV16: 1 | AW16: 1 | AX16: 1 | AY16: 1 | AZ16: 1 | BA16: 1 | BB16: 1 | BC16: 1 | BD16: 1 | BE16: 1 | BF16: 1 | BG16: 1 | BH16: 1 | BI16: 1 | BJ16: 1 | BK16: 1 | BL16: 1 | BM16: 1 | BN16: 1
B17: cfd_ref · selected | G17: =CHOOSE(Dashboard!$C$4,G14,G15,G16) -> 0.99940571 | H17: =CHOOSE(Dashboard!$C$4,H14,H15,H16) -> 0.99404549 | I17: =CHOOSE(Dashboard!$C$4,I14,I15,I16) -> 0.99400945 | J17: =CHOOSE(Dashboard!$C$4,J14,J15,J16) -> 0.99949249 | K17: =CHOOSE(Dashboard!$C$4,K14,K15,K16) -> 0.99404005 | L17: =CHOOSE(Dashboard!$C$4,L14,L15,L16) -> 0.99399973 | M17: =CHOOSE(Dashboard!$C$4,M14,M15,M16) -> 0.9995071 | N17: =CHOOSE(Dashboard!$C$4,N14,N15,N16) -> 0.99393184 | ... BN17: =CHOOSE(Dashboard!$C$4,BN14,BN15,BN16) -> 1
B18: fuel_ratio · low | G18: 1.0000381 | H18: 1.0000393 | I18: 1.0000393 | J18: 1.0000383 | K18: 1.0000397 | L18: 1.0000397 | M18: 1.0000383 | N18: 1.0000397 | O18: 1.0000397 | P18: 1.0000412 | Q18: 1.0000397 | R18: 1.0000397 | S18: 1.0000383 | T18: 1.0000397 | U18: 1.0000397 | V18: 1.0000383 | W18: 1.0000397 | X18: 1.0000397 | Y18: 1.0000383 | Z18: 1.0000418 | AA18: 1.0000397 | AB18: 1.0000383 | AC18: 1.0000397 | AD18: 1.0000397 | AE18: 1.0000383 | AF18: 1.0000397 | AG18: 1.0000397 | AH18: 1.0000383 | AI18: 1.0000397 | AJ18: 1.0000418 | AK18: 1.0000383 | AL18: 1.0000397 | AM18: 1.0000397 | AN18: 1.0000383 | AO18: 1.0000397 | AP18: 1.0000397 | AQ18: 1.0000383 | AR18: 1.0000413 | AS18: 1.0000413 | AT18: 1.0000428 | AU18: 1.0020515 | AV18: 1.0020519 | AW18: 1.0019875 | AX18: 1.0020578 | AY18: 1.002064 | AZ18: 1.0019935 | BA18: 1.0020698 | BB18: 1.0020716 | BC18: 1.0020021 | BD18: 1.0021909 | BE18: 1.0020802 | BF18: 1.0020091 | BG18: 1.0020828 | BH18: 1.0020843 | BI18: 1.0020131 | BJ18: 1.0020856 | BK18: 1.0020897 | BL18: 1.0020183 | BM18: 1.0020924 | BN18: 1.0022116
B19: fuel_ratio · central | G19: 1.0001515 | H19: 1.0001566 | I19: 1.0001566 | J19: 1.000147 | K19: 1.0001521 | L19: 1.0001518 | M19: 1.0001456 | N19: 1.0001521 | O19: 1.0001508 | P19: 1.0001553 | Q19: 1.0001496 | R19: 1.0001496 | S19: 1.0001446 | T19: 1.0001484 | U19: 1.0001456 | V19: 1.0001411 | W19: 1.0001499 | X19: 1.0001499 | Y19: 1.0001449 | Z19: 1.0001579 | AA19: 1.0001499 | AB19: 1.0001461 | AC19: 1.0001524 | AD19: 1.0001536 | AE19: 1.0001472 | AF19: 1.0001536 | AG19: 1.0001536 | AH19: 1.0001472 | AI19: 1.0001536 | AJ19: 1.0001605 | AK19: 1.0001472 | AL19: 1.0001536 | AM19: 1.0001536 | AN19: 1.0001472 | AO19: 1.0001536 | AP19: 1.0001536 | AQ19: 1.0001472 | AR19: 1.0001536 | AS19: 1.0001536 | AT19: 1.0001581 | AU19: 1.0020252 | AV19: 1.0020252 | AW19: 1.0019386 | AX19: 1.0020252 | AY19: 1.0020252 | AZ19: 1.0019386 | BA19: 1.0020252 | BB19: 1.0020252 | BC19: 1.0019386 | BD19: 1.0021198 | BE19: 1.0020252 | BF19: 1.0019386 | BG19: 1.0020252 | BH19: 1.0020252 | BI19: 1.0019386 | BJ19: 1.0020252 | BK19: 1.0020252 | BL19: 1.0019386 | BM19: 1.0020252 | BN19: 1.0021198
B20: fuel_ratio · high | G20: 1.0002178 | H20: 1.0002447 | I20: 1.0002564 | J20: 1.0002527 | K20: 1.0002767 | L20: 1.0002937 | M20: 1.0002846 | N20: 1.0003131 | O20: 1.000329 | P20: 1.0003405 | Q20: 1.0003671 | R20: 1.0003864 | S20: 1.0003721 | T20: 1.0003994 | U20: 1.0004035 | V20: 1.0003851 | W20: 1.0004076 | X20: 1.0004076 | Y20: 1.0003851 | Z20: 1.0004199 | AA20: 1.0004076 | AB20: 1.0003851 | AC20: 1.0004076 | AD20: 1.0004076 | AE20: 1.0003851 | AF20: 1.0004076 | AG20: 1.0004076 | AH20: 1.0003851 | AI20: 1.0004076 | AJ20: 1.0004199 | AK20: 1.0003851 | AL20: 1.0004076 | AM20: 1.0004076 | AN20: 1.0003851 | AO20: 1.0004076 | AP20: 1.0004076 | AQ20: 1.0003851 | AR20: 1.0004076 | AS20: 1.0004076 | AT20: 1.0004137 | AU20: 1.0019555 | AV20: 1.0019555 | AW20: 1.0018443 | AX20: 1.0019555 | AY20: 1.0019555 | AZ20: 1.0018443 | BA20: 1.0019555 | BB20: 1.0019555 | BC20: 1.0018443 | BD20: 1.0020163 | BE20: 1.0019555 | BF20: 1.0018443 | BG20: 1.0019555 | BH20: 1.0019555 | BI20: 1.0018443 | BJ20: 1.0019555 | BK20: 1.0019555 | BL20: 1.0018443 | BM20: 1.0019555 | BN20: 1.0020163
B21: fuel_ratio · selected | G21: =CHOOSE(Dashboard!$C$4,G18,G19,G20) -> 1.0001515 | H21: =CHOOSE(Dashboard!$C$4,H18,H19,H20) -> 1.0001566 | I21: =CHOOSE(Dashboard!$C$4,I18,I19,I20) -> 1.0001566 | J21: =CHOOSE(Dashboard!$C$4,J18,J19,J20) -> 1.000147 | K21: =CHOOSE(Dashboard!$C$4,K18,K19,K20) -> 1.0001521 | L21: =CHOOSE(Dashboard!$C$4,L18,L19,L20) -> 1.0001518 | M21: =CHOOSE(Dashboard!$C$4,M18,M19,M20) -> 1.0001456 | N21: =CHOOSE(Dashboard!$C$4,N18,N19,N20) -> 1.0001521 | ... BN21: =CHOOSE(Dashboard!$C$4,BN18,BN19,BN20) -> 1.0021198
B23: SMR · fixed price = last-12-month average spot
B24: cf · low | G24: 0.95 | H24: 0.91876712 | I24: 0.91876712 | J24: 0.98 | K24: 0.94778082 | L24: 0.94778082 | M24: 0.98 | N24: 0.94778082 | O24: 0.94778082 | P24: 0.91287671 | Q24: 0.94778082 | R24: 0.94778082 | S24: 0.98 | T24: 0.94778082 | U24: 0.94778082 | V24: 0.98 | W24: 0.94778082 | X24: 0.94778082 | Y24: 0.98 | Z24: 0.89945205 | AA24: 0.94778082 | AB24: 0.98 | AC24: 0.94778082 | AD24: 0.94778082 | AE24: 0.98 | AF24: 0.94778082 | AG24: 0.94778082 | AH24: 0.98 | AI24: 0.94778082 | AJ24: 0.89945205 | AK24: 0.98 | AL24: 0.94778082 | AM24: 0.94778082 | AN24: 0.98 | AO24: 0.94778082 | AP24: 0.94778082 | AQ24: 0.98 | AR24: 0.94778082 | AS24: 0.94778082 | AT24: 0.91287671 | AU24: 0.94778082 | AV24: 0.94778082 | AW24: 0.98 | AX24: 0.94778082 | AY24: 0.94778082 | AZ24: 0.98 | BA24: 0.94778082 | BB24: 0.94778082 | BC24: 0.98 | BD24: 0.89945205 | BE24: 0.94778082 | BF24: 0.98 | BG24: 0.94778082 | BH24: 0.94778082 | BI24: 0.98 | BJ24: 0.94778082 | BK24: 0.94778082 | BL24: 0.98 | BM24: 0.94778082 | BN24: 0.89945205
B25: cf · central | G25: 0.94 | H25: 0.90136986 | I25: 0.90136986 | J25: 0.97 | K25: 0.93013699 | L25: 0.93013699 | M25: 0.97 | N25: 0.93013699 | O25: 0.93013699 | P25: 0.90356164 | Q25: 0.93013699 | R25: 0.93013699 | S25: 0.97 | T25: 0.93013699 | U25: 0.93013699 | V25: 0.97 | W25: 0.93013699 | X25: 0.93013699 | Y25: 0.97 | Z25: 0.89027397 | AA25: 0.93013699 | AB25: 0.97 | AC25: 0.93013699 | AD25: 0.93013699 | AE25: 0.97 | AF25: 0.93013699 | AG25: 0.93013699 | AH25: 0.97 | AI25: 0.93013699 | AJ25: 0.89027397 | AK25: 0.97 | AL25: 0.93013699 | AM25: 0.93013699 | AN25: 0.97 | AO25: 0.93013699 | AP25: 0.93013699 | AQ25: 0.97 | AR25: 0.93013699 | AS25: 0.93013699 | AT25: 0.90356164 | AU25: 0.93013699 | AV25: 0.93013699 | AW25: 0.97 | AX25: 0.93013699 | AY25: 0.93013699 | AZ25: 0.97 | BA25: 0.93013699 | BB25: 0.93013699 | BC25: 0.97 | BD25: 0.89027397 | BE25: 0.93013699 | BF25: 0.97 | BG25: 0.93013699 | BH25: 0.93013699 | BI25: 0.97 | BJ25: 0.93013699 | BK25: 0.93013699 | BL25: 0.97 | BM25: 0.93013699 | BN25: 0.89027397
B26: cf · high | G26: 0.92 | H26: 0.86958904 | I26: 0.86958904 | J26: 0.95 | K26: 0.89794521 | L26: 0.89794521 | M26: 0.95 | N26: 0.89794521 | O26: 0.89794521 | P26: 0.88493151 | Q26: 0.89794521 | R26: 0.89794521 | S26: 0.95 | T26: 0.89794521 | U26: 0.89794521 | V26: 0.95 | W26: 0.89794521 | X26: 0.89794521 | Y26: 0.95 | Z26: 0.87191781 | AA26: 0.89794521 | AB26: 0.95 | AC26: 0.89794521 | AD26: 0.89794521 | AE26: 0.95 | AF26: 0.89794521 | AG26: 0.89794521 | AH26: 0.95 | AI26: 0.89794521 | AJ26: 0.87191781 | AK26: 0.95 | AL26: 0.89794521 | AM26: 0.89794521 | AN26: 0.95 | AO26: 0.89794521 | AP26: 0.89794521 | AQ26: 0.95 | AR26: 0.89794521 | AS26: 0.89794521 | AT26: 0.88493151 | AU26: 0.89794521 | AV26: 0.89794521 | AW26: 0.95 | AX26: 0.89794521 | AY26: 0.89794521 | AZ26: 0.95 | BA26: 0.89794521 | BB26: 0.89794521 | BC26: 0.95 | BD26: 0.87191781 | BE26: 0.89794521 | BF26: 0.95 | BG26: 0.89794521 | BH26: 0.89794521 | BI26: 0.95 | BJ26: 0.89794521 | BK26: 0.89794521 | BL26: 0.95 | BM26: 0.89794521 | BN26: 0.87191781
B27: cf · selected | G27: =CHOOSE(Dashboard!$C$4,G24,G25,G26) -> 0.94 | H27: =CHOOSE(Dashboard!$C$4,H24,H25,H26) -> 0.90136986 | I27: =CHOOSE(Dashboard!$C$4,I24,I25,I26) -> 0.90136986 | J27: =CHOOSE(Dashboard!$C$4,J24,J25,J26) -> 0.97 | K27: =CHOOSE(Dashboard!$C$4,K24,K25,K26) -> 0.93013699 | L27: =CHOOSE(Dashboard!$C$4,L24,L25,L26) -> 0.93013699 | M27: =CHOOSE(Dashboard!$C$4,M24,M25,M26) -> 0.97 | N27: =CHOOSE(Dashboard!$C$4,N24,N25,N26) -> 0.93013699 | ... BN27: =CHOOSE(Dashboard!$C$4,BN24,BN25,BN26) -> 0.89027397
B28: fuel_ratio · low | G28: 1 | H28: 1 | I28: 1 | J28: 1 | K28: 1 | L28: 1 | M28: 1 | N28: 1 | O28: 1 | P28: 1 | Q28: 1 | R28: 1 | S28: 1 | T28: 1 | U28: 1 | V28: 1 | W28: 1 | X28: 1 | Y28: 1 | Z28: 1 | AA28: 1 | AB28: 1 | AC28: 1 | AD28: 1 | AE28: 1 | AF28: 1 | AG28: 1 | AH28: 1 | AI28: 1 | AJ28: 1 | AK28: 1 | AL28: 1 | AM28: 1 | AN28: 1 | AO28: 1 | AP28: 1 | AQ28: 1 | AR28: 1 | AS28: 1 | AT28: 1 | AU28: 1 | AV28: 1 | AW28: 1 | AX28: 1 | AY28: 1 | AZ28: 1 | BA28: 1 | BB28: 1 | BC28: 1 | BD28: 1 | BE28: 1 | BF28: 1 | BG28: 1 | BH28: 1 | BI28: 1 | BJ28: 1 | BK28: 1 | BL28: 1 | BM28: 1 | BN28: 1
B29: fuel_ratio · central | G29: 1 | H29: 1 | I29: 1 | J29: 1 | K29: 1 | L29: 1 | M29: 1 | N29: 1 | O29: 1 | P29: 1 | Q29: 1 | R29: 1 | S29: 1 | T29: 1 | U29: 1 | V29: 1 | W29: 1 | X29: 1 | Y29: 1 | Z29: 1 | AA29: 1 | AB29: 1 | AC29: 1 | AD29: 1 | AE29: 1 | AF29: 1 | AG29: 1 | AH29: 1 | AI29: 1 | AJ29: 1 | AK29: 1 | AL29: 1 | AM29: 1 | AN29: 1 | AO29: 1 | AP29: 1 | AQ29: 1 | AR29: 1 | AS29: 1 | AT29: 1 | AU29: 1 | AV29: 1 | AW29: 1 | AX29: 1 | AY29: 1 | AZ29: 1 | BA29: 1 | BB29: 1 | BC29: 1 | BD29: 1 | BE29: 1 | BF29: 1 | BG29: 1 | BH29: 1 | BI29: 1 | BJ29: 1 | BK29: 1 | BL29: 1 | BM29: 1 | BN29: 1
B30: fuel_ratio · high | G30: 1 | H30: 1 | I30: 1 | J30: 1 | K30: 1 | L30: 1 | M30: 1 | N30: 1 | O30: 1 | P30: 1 | Q30: 1 | R30: 1 | S30: 1 | T30: 1 | U30: 1 | V30: 1 | W30: 1 | X30: 1 | Y30: 1 | Z30: 1 | AA30: 1 | AB30: 1 | AC30: 1 | AD30: 1 | AE30: 1 | AF30: 1 | AG30: 1 | AH30: 1 | AI30: 1 | AJ30: 1 | AK30: 1 | AL30: 1 | AM30: 1 | AN30: 1 | AO30: 1 | AP30: 1 | AQ30: 1 | AR30: 1 | AS30: 1 | AT30: 1 | AU30: 1 | AV30: 1 | AW30: 1 | AX30: 1 | AY30: 1 | AZ30: 1 | BA30: 1 | BB30: 1 | BC30: 1 | BD30: 1 | BE30: 1 | BF30: 1 | BG30: 1 | BH30: 1 | BI30: 1 | BJ30: 1 | BK30: 1 | BL30: 1 | BM30: 1 | BN30: 1
B31: fuel_ratio · selected | G31: =CHOOSE(Dashboard!$C$4,G28,G29,G30) -> 1 | H31: =CHOOSE(Dashboard!$C$4,H28,H29,H30) -> 1 | I31: =CHOOSE(Dashboard!$C$4,I28,I29,I30) -> 1 | J31: =CHOOSE(Dashboard!$C$4,J28,J29,J30) -> 1 | K31: =CHOOSE(Dashboard!$C$4,K28,K29,K30) -> 1 | L31: =CHOOSE(Dashboard!$C$4,L28,L29,L30) -> 1 | M31: =CHOOSE(Dashboard!$C$4,M28,M29,M30) -> 1 | N31: =CHOOSE(Dashboard!$C$4,N28,N29,N30) -> 1 | ... BN31: =CHOOSE(Dashboard!$C$4,BN28,BN29,BN30) -> 1
B33: SMR · merchant, dynamic 50–100 % dispatch
B34: cf · low | G34: 0.91619578 | H34: 0.88492295 | I34: 0.88477169 | J34: 0.94493607 | K34: 0.91265297 | L34: 0.912621 | M34: 0.94484018 | N34: 0.91254909 | O34: 0.91251712 | P34: 0.87751712 | Q34: 0.91234932 | R34: 0.91226142 | S34: 0.94444863 | T34: 0.91214155 | U34: 0.91208562 | V34: 0.9442089 | W34: 0.91198973 | X34: 0.91198973 | Y34: 0.94416096 | Z34: 0.86351712 | AA34: 0.91184589 | AB34: 0.94406507 | AC34: 0.91181393 | AD34: 0.91181393 | AE34: 0.9440411 | AF34: 0.91175799 | AG34: 0.91168607 | AH34: 0.94387329 | AI34: 0.91165411 | AJ34: 0.86332534 | AK34: 0.94384132 | AL34: 0.91162215 | AM34: 0.91162215 | AN34: 0.94384132 | AO34: 0.91162215 | AP34: 0.91159018 | AQ34: 0.94372945 | AR34: 0.91151027 | AS34: 0.9114863 | AT34: 0.87655023 | AU34: 0.91140639 | AV34: 0.9113984 | AW34: 0.94352169 | AX34: 0.91130251 | AY34: 0.91119863 | AZ34: 0.94341781 | BA34: 0.91110274 | BB34: 0.91107078 | BC34: 0.94326598 | BD34: 0.86268607 | BE34: 0.91093493 | BF34: 0.94315411 | BG34: 0.91088699 | BH34: 0.910871 | BI34: 0.94309018 | BJ34: 0.91084703 | BK34: 0.91078311 | BL34: 0.94300228 | BM34: 0.91074315 | BN34: 0.86238242
B35: cf · central | G35: 0.89515168 | H35: 0.85687909 | I35: 0.85677195 | J35: 0.92355781 | K35: 0.8841427 | L35: 0.8840395 | M35: 0.92342416 | N35: 0.88396337 | O35: 0.88393292 | P35: 0.85756708 | Q35: 0.88375359 | R35: 0.88367464 | S35: 0.92298035 | T35: 0.88359569 | U35: 0.88335884 | V35: 0.92271305 | W35: 0.88309154 | X35: 0.88298834 | Y35: 0.92233973 | Z35: 0.84347624 | AA35: 0.88283045 | AB35: 0.92200532 | AC35: 0.88245656 | AD35: 0.88245656 | AE35: 0.92178652 | AF35: 0.88226821 | AG35: 0.88226201 | AH35: 0.92164666 | AI35: 0.88226201 | AJ35: 0.84287735 | AK35: 0.92164666 | AL35: 0.88226201 | AM35: 0.88226201 | AN35: 0.92164666 | AO35: 0.88226201 | AP35: 0.88226201 | AQ35: 0.92164666 | AR35: 0.88226201 | AS35: 0.88226201 | AT35: 0.85600557 | AU35: 0.88226201 | AV35: 0.88226201 | AW35: 0.92164666 | AX35: 0.88226201 | AY35: 0.88226201 | AZ35: 0.92164666 | BA35: 0.88226201 | BB35: 0.88226201 | BC35: 0.92164666 | BD35: 0.84287735 | BE35: 0.88226201 | BF35: 0.92164666 | BG35: 0.88226201 | BH35: 0.88226201 | BI35: 0.92164666 | BJ35: 0.88226201 | BK35: 0.88226201 | BL35: 0.92164666 | BM35: 0.88226201 | BN35: 0.84287735
B36: cf · high | G36: 0.86843326 | H36: 0.81905514 | I36: 0.81910436 | J36: 0.89706638 | K36: 0.8459492 | L36: 0.84597717 | M36: 0.89693213 | N36: 0.84589047 | O36: 0.84583453 | P36: 0.83305873 | Q36: 0.84581495 | R36: 0.84581495 | S36: 0.89681747 | T36: 0.8457758 | U36: 0.84574783 | V36: 0.89681467 | W36: 0.84580097 | X36: 0.84580097 | Y36: 0.89681467 | Z36: 0.82029412 | AA36: 0.84580097 | AB36: 0.89681467 | AC36: 0.84580097 | AD36: 0.84580097 | AE36: 0.89681467 | AF36: 0.84580097 | AG36: 0.84580097 | AH36: 0.89681467 | AI36: 0.84580097 | AJ36: 0.82029412 | AK36: 0.89681467 | AL36: 0.84580097 | AM36: 0.84580097 | AN36: 0.89681467 | AO36: 0.84580097 | AP36: 0.84580097 | AQ36: 0.89681467 | AR36: 0.84580097 | AS36: 0.84580097 | AT36: 0.83304755 | AU36: 0.84580097 | AV36: 0.84580097 | AW36: 0.89681467 | AX36: 0.84580097 | AY36: 0.84580097 | AZ36: 0.89681467 | BA36: 0.84580097 | BB36: 0.84580097 | BC36: 0.89681467 | BD36: 0.82029412 | BE36: 0.84580097 | BF36: 0.89681467 | BG36: 0.84580097 | BH36: 0.84580097 | BI36: 0.89681467 | BJ36: 0.84580097 | BK36: 0.84580097 | BL36: 0.89681467 | BM36: 0.84580097 | BN36: 0.82029412
B37: cf · selected | G37: =CHOOSE(Dashboard!$C$4,G34,G35,G36) -> 0.89515168 | H37: =CHOOSE(Dashboard!$C$4,H34,H35,H36) -> 0.85687909 | I37: =CHOOSE(Dashboard!$C$4,I34,I35,I36) -> 0.85677195 | J37: =CHOOSE(Dashboard!$C$4,J34,J35,J36) -> 0.92355781 | K37: =CHOOSE(Dashboard!$C$4,K34,K35,K36) -> 0.8841427 | L37: =CHOOSE(Dashboard!$C$4,L34,L35,L36) -> 0.8840395 | M37: =CHOOSE(Dashboard!$C$4,M34,M35,M36) -> 0.92342416 | N37: =CHOOSE(Dashboard!$C$4,N34,N35,N36) -> 0.88396337 | ... BN37: =CHOOSE(Dashboard!$C$4,BN34,BN35,BN36) -> 0.84287735
B38: capture · low | G38: 1.039907 | H38: 1.0356591 | I38: 1.0358059 | J38: 1.0400951 | K38: 1.0358284 | L38: 1.0358565 | M38: 1.0402219 | N38: 1.0359205 | O38: 1.0359487 | P38: 1.0376919 | Q38: 1.036104 | R38: 1.0361855 | S38: 1.0406605 | T38: 1.0362954 | U38: 1.0363465 | V38: 1.0409206 | W38: 1.0364338 | X38: 1.036432 | Y38: 1.0410042 | Z38: 1.0408891 | AA38: 1.0365631 | AB38: 1.0411323 | AC38: 1.0365901 | AD38: 1.0365884 | AE38: 1.0411943 | AF38: 1.0366383 | AG38: 1.036705 | AH38: 1.0413893 | AI38: 1.0367325 | AJ38: 1.0407833 | AK38: 1.0414594 | AL38: 1.0367587 | AM38: 1.0367573 | AN38: 1.0415002 | AO38: 1.0367545 | AP38: 1.0367835 | AQ38: 1.0416441 | AR38: 1.0368567 | AS38: 1.0368782 | AT38: 1.0380077 | AU38: 1.0369517 | AV38: 1.0369582 | AW38: 1.0419184 | AX38: 1.0370473 | AY38: 1.037145 | AZ38: 1.0420564 | BA38: 1.0372343 | BB38: 1.0372639 | BC38: 1.042239 | BD38: 1.0408382 | BE38: 1.0373909 | BF38: 1.0423851 | BG38: 1.0374353 | BH38: 1.0374499 | BI38: 1.0424873 | BJ38: 1.0374717 | BK38: 1.037532 | BL38: 1.042612 | BM38: 1.0375692 | BN38: 1.0408562
B39: capture · central | G39: 1.0405393 | H39: 1.0369578 | I39: 1.0370533 | J39: 1.0407408 | K39: 1.0369701 | L39: 1.037058 | M39: 1.0409445 | N39: 1.0371071 | O39: 1.0371242 | P39: 1.0378909 | Q39: 1.0372763 | R39: 1.037341 | S39: 1.0415226 | T39: 1.0373942 | U39: 1.0376157 | V39: 1.041857 | W39: 1.0378564 | X39: 1.0379458 | Y39: 1.0422946 | Z39: 1.0410687 | AA39: 1.0380708 | AB39: 1.0426967 | AC39: 1.0384175 | AD39: 1.0384078 | AE39: 1.0429902 | AF39: 1.0385727 | AG39: 1.0385695 | AH39: 1.043181 | AI39: 1.0385695 | AJ39: 1.0412836 | AK39: 1.043181 | AL39: 1.0385695 | AM39: 1.0385695 | AN39: 1.043181 | AO39: 1.0385695 | AP39: 1.0385695 | AQ39: 1.043181 | AR39: 1.0385695 | AS39: 1.0385695 | AT39: 1.0387701 | AU39: 1.0385695 | AV39: 1.0385695 | AW39: 1.043181 | AX39: 1.0385695 | AY39: 1.0385695 | AZ39: 1.043181 | BA39: 1.0385695 | BB39: 1.0385695 | BC39: 1.043181 | BD39: 1.0412836 | BE39: 1.0385695 | BF39: 1.043181 | BG39: 1.0385695 | BH39: 1.0385695 | BI39: 1.043181 | BJ39: 1.0385695 | BK39: 1.0385695 | BL39: 1.043181 | BM39: 1.0385695 | BN39: 1.0412836
B40: capture · high | G40: 1.0412437 | H40: 1.0372934 | I40: 1.0372007 | J40: 1.0410253 | K40: 1.0369485 | L40: 1.0368791 | M40: 1.0412764 | N40: 1.0368858 | O40: 1.0369036 | P40: 1.0375407 | Q40: 1.0368436 | R40: 1.0368038 | S40: 1.0416299 | T40: 1.0367631 | U40: 1.0367523 | V40: 1.0417284 | W40: 1.0366849 | X40: 1.0366849 | Y40: 1.0417284 | Z40: 1.0396989 | AA40: 1.0366849 | AB40: 1.0417284 | AC40: 1.0366849 | AD40: 1.0366849 | AE40: 1.0417284 | AF40: 1.0366849 | AG40: 1.0366849 | AH40: 1.0417284 | AI40: 1.0366849 | AJ40: 1.0396989 | AK40: 1.0417284 | AL40: 1.0366849 | AM40: 1.0366849 | AN40: 1.0417284 | AO40: 1.0366849 | AP40: 1.0366849 | AQ40: 1.0417284 | AR40: 1.0366849 | AS40: 1.0366849 | AT40: 1.0372142 | AU40: 1.0366849 | AV40: 1.0366849 | AW40: 1.0417284 | AX40: 1.0366849 | AY40: 1.0366849 | AZ40: 1.0417284 | BA40: 1.0366849 | BB40: 1.0366849 | BC40: 1.0417284 | BD40: 1.0396989 | BE40: 1.0366849 | BF40: 1.0417284 | BG40: 1.0366849 | BH40: 1.0366849 | BI40: 1.0417284 | BJ40: 1.0366849 | BK40: 1.0366849 | BL40: 1.0417284 | BM40: 1.0366849 | BN40: 1.0396989
B41: capture · selected | G41: =CHOOSE(Dashboard!$C$4,G38,G39,G40) -> 1.0405393 | H41: =CHOOSE(Dashboard!$C$4,H38,H39,H40) -> 1.0369578 | I41: =CHOOSE(Dashboard!$C$4,I38,I39,I40) -> 1.0370533 | J41: =CHOOSE(Dashboard!$C$4,J38,J39,J40) -> 1.0407408 | K41: =CHOOSE(Dashboard!$C$4,K38,K39,K40) -> 1.0369701 | L41: =CHOOSE(Dashboard!$C$4,L38,L39,L40) -> 1.037058 | M41: =CHOOSE(Dashboard!$C$4,M38,M39,M40) -> 1.0409445 | N41: =CHOOSE(Dashboard!$C$4,N38,N39,N40) -> 1.0371071 | ... BN41: =CHOOSE(Dashboard!$C$4,BN38,BN39,BN40) -> 1.0412836
B42: fuel_ratio · low | G42: 1.0018884 | H42: 1.0019578 | I42: 1.0019669 | J42: 1.0019073 | K42: 1.0019781 | L42: 1.0019799 | M42: 1.0019124 | N42: 1.0019833 | O42: 1.001985 | P42: 1.00207 | Q42: 1.0019942 | R42: 1.0019996 | S42: 1.0019331 | T42: 1.0020061 | U42: 1.0020092 | V42: 1.0019463 | W42: 1.002015 | X42: 1.002015 | Y42: 1.0019493 | Z42: 1.0021373 | AA42: 1.002024 | AB42: 1.0019549 | AC42: 1.0020258 | AD42: 1.0020258 | AE42: 1.0019562 | AF42: 1.0020294 | AG42: 1.0020339 | AH42: 1.0019662 | AI42: 1.0020357 | AJ42: 1.0021496 | AK42: 1.0019679 | AL42: 1.0020374 | AM42: 1.0020374 | AN42: 1.0019679 | AO42: 1.0020374 | AP42: 1.0020391 | AQ42: 1.0019749 | AR42: 1.0020447 | AS42: 1.002046 | AT42: 1.0021293 | AU42: 1.0020515 | AV42: 1.0020519 | AW42: 1.0019875 | AX42: 1.0020578 | AY42: 1.002064 | AZ42: 1.0019935 | BA42: 1.0020698 | BB42: 1.0020716 | BC42: 1.0020021 | BD42: 1.0021909 | BE42: 1.0020802 | BF42: 1.0020091 | BG42: 1.0020828 | BH42: 1.0020843 | BI42: 1.0020131 | BJ42: 1.0020856 | BK42: 1.0020897 | BL42: 1.0020183 | BM42: 1.0020924 | BN42: 1.0022116
B43: fuel_ratio · central | G43: 1.0018154 | H43: 1.0019021 | I43: 1.001908 | J43: 1.0018298 | K43: 1.001913 | L43: 1.0019185 | M43: 1.0018367 | N43: 1.0019231 | O43: 1.0019247 | P43: 1.0019908 | Q43: 1.0019359 | R43: 1.0019412 | S43: 1.0018625 | T43: 1.0019455 | U43: 1.0019593 | V43: 1.0018772 | W43: 1.0019758 | X43: 1.0019824 | Y43: 1.0019 | Z43: 1.0020833 | AA43: 1.001992 | AB43: 1.0019192 | AC43: 1.0020147 | AD43: 1.0020147 | AE43: 1.0019314 | AF43: 1.0020249 | AG43: 1.0020252 | AH43: 1.0019386 | AI43: 1.0020252 | AJ43: 1.0021198 | AK43: 1.0019386 | AL43: 1.0020252 | AM43: 1.0020252 | AN43: 1.0019386 | AO43: 1.0020252 | AP43: 1.0020252 | AQ43: 1.0019386 | AR43: 1.0020252 | AS43: 1.0020252 | AT43: 1.0020873 | AU43: 1.0020252 | AV43: 1.0020252 | AW43: 1.0019386 | AX43: 1.0020252 | AY43: 1.0020252 | AZ43: 1.0019386 | BA43: 1.0020252 | BB43: 1.0020252 | BC43: 1.0019386 | BD43: 1.0021198 | BE43: 1.0020252 | BF43: 1.0019386 | BG43: 1.0020252 | BH43: 1.0020252 | BI43: 1.0019386 | BJ43: 1.0020252 | BK43: 1.0020252 | BL43: 1.0019386 | BM43: 1.0020252 | BN43: 1.0021198
...

Sheet Model_SMR_CfD
B1: SMR · CfD (two-way, PEJ template)
B2: Annual model, real PLN m (2026). Column D = totals / KPIs. Timeline columns G→. Dispatch quantities come from the Twin sheet (hourly digital twin).
B4: Year | G4: 2027 | H4: 2028 | I4: 2029 | J4: 2030 | K4: 2031 | L4: 2032 | M4: 2033 | N4: 2034 | O4: 2035 | P4: 2036 | Q4: 2037 | R4: 2038 | S4: 2039 | T4: 2040 | U4: 2041 | V4: 2042 | W4: 2043 | X4: 2044 | Y4: 2045 | Z4: 2046 | AA4: 2047 | AB4: 2048 | AC4: 2049 | AD4: 2050 | AE4: 2051 | AF4: 2052 | AG4: 2053 | AH4: 2054 | AI4: 2055 | AJ4: 2056 | AK4: 2057 | AL4: 2058 | AM4: 2059 | AN4: 2060 | AO4: 2061 | AP4: 2062 | AQ4: 2063 | AR4: 2064 | AS4: 2065 | AT4: 2066 | AU4: 2067 | AV4: 2068 | AW4: 2069 | AX4: 2070 | AY4: 2071 | AZ4: 2072 | BA4: 2073 | BB4: 2074 | BC4: 2075 | BD4: 2076 | BE4: 2077 | BF4: 2078 | BG4: 2079 | BH4: 2080 | BI4: 2081 | BJ4: 2082 | BK4: 2083 | BL4: 2084 | BM4: 2085 | BN4: 2086 | BO4: 2087 | BP4: 2088 | BQ4: 2089 | BR4: 2090 | BS4: 2091 | BT4: 2092 | BU4: 2093 | BV4: 2094 | BW4: 2095 | BX4: 2096
B6: 1. Parameters (links to Input, selected case)
B7: Net capacity, MW | D7: =Input!$H$52 -> 300
B8: Overnight capex, PLN/kW | D8: =Input!$H$53 -> 38000
B9: Construction years | D9: =Input!$H$54 -> 5
B10: COD year | D10: =Input!$H$55 -> 2035
B11: Life years | D11: =Input!$H$56 -> 60
B12: FID year (COD − construction) | D12: =$D$10-$D$9 -> 2030
